{
 "cells": [
  {
   "cell_type": "code",
   "execution_count": null,
   "id": "4a939bb0-cf02-4f6a-bd53-535a7f5b69a5",
   "metadata": {},
   "outputs": [],
   "source": [
    "##Q1\n",
    "In Python, an exception is an event that occurs during the execution of a \n",
    "program that disrupts the normal flow of the program's instructions. When an \n",
    "exceptional situation arises, Python raises an exception, which can be \n",
    "caught and handled by the program's code. Exceptions allow you to gracefully \n",
    "handle errors and unexpected conditions, enhancing the reliability and \n",
    "robustness of your code.\n",
    "\n",
    "difference between exceptions and Syntax errors:\n",
    "    \n",
    "An Exception is an event that occurs during the program execution and\n",
    "disrupts the normal flow of the program's execution. Errors mostly happen\n",
    "at compile-time like syntax error; however it can happen at runtime as well.\n",
    "Whereas an Exception occurs at runtime (checked exceptions can be detected \n",
    "at compile time)."
   ]
  },
  {
   "cell_type": "code",
   "execution_count": null,
   "id": "1dda243e-6d6d-4202-a7f8-3236f7cace44",
   "metadata": {},
   "outputs": [],
   "source": [
    "##Q2\n",
    "When an exception is not handled, it propagates up the call stack until it reaches the top level of the program. If the exception is still not \n",
    "handled at this point, the program will terminate, and an error message will be displayed, indicating the type of exception that occurred and \n",
    "possibly a traceback showing the sequence of function calls that led to the exception.\n",
    "\n",
    "Example:\n",
    "def divide(a, b):\n",
    "    return a / b\n",
    "\n",
    "def main():\n",
    "    try:\n",
    "        result = divide(10, 0)  # This will raise a ZeroDivisionError\n",
    "        print(\"Result:\", result)\n",
    "    except ValueError:\n",
    "        print(\"Caught a ValueError\")\n",
    "    \n",
    "main()\n"
   ]
  },
  {
   "cell_type": "code",
   "execution_count": null,
   "id": "be048466-9d57-4898-94b2-c6a4a75fdf30",
   "metadata": {},
   "outputs": [],
   "source": [
    "##Q3\n",
    "In Python, the try , except , else , finally  statements are used to catch and handle exceptions. The try block contains the code that might raise an exception,\n",
    "and the except block is used to specify the actions to be taken if a specific exception occurs.\n",
    "example:\n",
    " def divide(a, b):\n",
    "    try:\n",
    "        result = a / b\n",
    "    except ZeroDivisionError:\n",
    "        print(\"Error: Division by zero\")\n",
    "    else:\n",
    "        print(\"Result:\", result)\n",
    "    finally:\n",
    "        print(\"Execution completed.\")\n",
    "\n",
    "# Example 1: Division by non-zero number\n",
    "divide(10, 2)\n",
    "# Output:\n",
    "# Result: 5.0\n",
    "# Execution completed.\n",
    "\n",
    "# Example 2: Division by zero\n",
    "divide(10, 0)\n",
    "# Output:\n",
    "# Error: Division by zero\n",
    "# Execution completed.\n",
    "\n",
    "# Example 3: Division by string (ValueError)\n",
    "divide(10, '2')\n",
    "# Output:\n",
    "# Execution completed.\n",
    "# Traceback (most recent call last):\n",
    "#   ...\n",
    "# TypeError: unsupported operand type(s) for /: 'int' and 'str'\n"
   ]
  },
  {
   "cell_type": "code",
   "execution_count": null,
   "id": "fbf1b30d-829b-4583-9fe6-ae7c14552138",
   "metadata": {},
   "outputs": [],
   "source": [
    "##Q4\n",
    "Certainly! In Python, the try and else blocks are used together to structure exception handling code. The try block contains the code that might \n",
    "raise an exception, and the else block contains code that should be executed only if no exception occurs in the try block.\n",
    "\n",
    "example:\n",
    "    \n",
    "def divide(a, b):\n",
    "    try:\n",
    "        result = a / b\n",
    "    except ZeroDivisionError:\n",
    "        print(\"Error: Division by zero\")\n",
    "    else:\n",
    "        print(\"Result:\", result)\n",
    "\n",
    "# Example 1: Division by non-zero number\n",
    "divide(10, 2)\n",
    "# Output:\n",
    "# Result: 5.0\n",
    "\n",
    "# Example 2: Division by zero\n",
    "divide(10, 0)\n",
    "# Output:\n",
    "# Error: Division by zero\n",
    "\n",
    "\n",
    "\n",
    "In Python, the finally block is used in conjunction with the try and except blocks to define a set of statements that will be executed \n",
    "regardless of whether an exception occurred or not. The finally block is often used for cleanup operations or tasks that need to be performed \n",
    "regardless of the outcome of the code in the try block.\n",
    "\n",
    "Example:\n",
    "\n",
    "def divide(a, b):\n",
    "    try:\n",
    "        result = a / b\n",
    "        print(\"Result:\", result)\n",
    "    except ZeroDivisionError:\n",
    "        print(\"Error: Division by zero\")\n",
    "    finally:\n",
    "        print(\"Execution completed.\")\n",
    "\n",
    "# Example 1: Division by non-zero number\n",
    "divide(10, 2)\n",
    "# Output:\n",
    "# Result: 5.0\n",
    "# Execution completed.\n",
    "\n",
    "# Example 2: Division by zero\n",
    "divide(10, 0)\n",
    "# Output:\n",
    "# Error: Division by zero\n",
    "# Execution completed.\n",
    "\n",
    "\n",
    "In Python, the raise statement is used to explicitly raise an exception. You can use it to signal that a specific exception should be raised at\n",
    "a particular point in your code. This can be useful when you want to handle certain situations that aren't covered by existing exceptions or when \n",
    "you want to create your own custom exceptions.\n",
    "\n",
    "Example \n",
    "\n",
    "\n",
    "def check_age(age):\n",
    "    if age < 0:\n",
    "        raise ValueError(\"Age cannot be negative\")\n",
    "    elif age < 18:\n",
    "        raise ValueError(\"You must be at least 18 years old\")\n",
    "    else:\n",
    "        print(\"Age is valid\")\n",
    "\n",
    "try:\n",
    "    user_age = int(input(\"Enter your age: \"))\n",
    "    check_age(user_age)\n",
    "except ValueError as ve:\n",
    "    print(\"Error:\", ve)\n"
   ]
  },
  {
   "cell_type": "code",
   "execution_count": null,
   "id": "af50caac-f4a3-4809-b316-d92f3dcf82ea",
   "metadata": {},
   "outputs": [],
   "source": [
    "##Q5\n",
    "Custom exceptions, also known as user-defined exceptions, are exceptions that you define yourself by creating new exception classes. These \n",
    "classes inherit from the base Exception class or one of its subclasses. Custom exceptions allow you to handle specific error scenarios that are \n",
    "not adequately covered by built-in exceptions. They provide more descriptive and meaningful error messages, making it easier to understand and \n",
    "debug the issues in your code.\n",
    "\n",
    "Why do we need custom exceptions?\n",
    "\n",
    "1. Clarity: Custom exceptions help make your code more readable and maintainable. By defining exceptions with meaningful names, you can communicate the nature of the error more effectively to other developers\n",
    "who read your code.\n",
    "2. Specificity: Custom exceptions let you capture specific error conditions in your application that might not be covered by standard exceptions.\n",
    "This allows for better error handling and differentiation between different types of issues.\n",
    "3. Modularity: By creating custom exceptions, you can encapsulate error-handling logic for specific situations in a clean and modular way. This \n",
    "promotes separation of concerns and helps maintain code structure.\n",
    "\n",
    "Example:\n",
    "\n",
    "class InsufficientFundsError(Exception):\n",
    "    def __init__(self, balance, amount):\n",
    "        self.balance = balance\n",
    "        self.amount = amount\n",
    "        self.message = f\"Insufficient funds. Balance: {balance}, Withdrawal amount: {amount}\"\n",
    "\n",
    "def withdraw(balance, amount):\n",
    "    if amount > balance:\n",
    "        raise InsufficientFundsError(balance, amount)\n",
    "    else:\n",
    "        print(\"Withdrawal successful\")\n",
    "\n",
    "try:\n",
    "    account_balance = 100\n",
    "    withdrawal_amount = 150\n",
    "    withdraw(account_balance, withdrawal_amount)\n",
    "except InsufficientFundsError as ife:\n",
    "    print(\"Error:\", ife.message)\n",
    "\n"
   ]
  },
  {
   "cell_type": "code",
   "execution_count": null,
   "id": "14bb7c16-fbff-44ed-b3e8-46ca62b66616",
   "metadata": {},
   "outputs": [],
   "source": [
    "##Q6\n",
    "\n",
    "class MyCustomException(Exception):\n",
    "    def __init__(self, message):\n",
    "        self.message = message\n",
    "        super().__init__(self.message)\n",
    "\n",
    "def example_function(number):\n",
    "    if number < 0:\n",
    "        raise MyCustomException(\"Number should be non-negative.\")\n",
    "    else:\n",
    "        print(\"Number is:\", number)\n",
    "\n",
    "try:\n",
    "    user_input = int(input(\"Enter a number: \"))\n",
    "    example_function(user_input)\n",
    "except MyCustomException as mce:\n",
    "    print(\"Custom Exception:\", mce.message)\n",
    "except ValueError:\n",
    "    print(\"Invalid input. Please enter a valid number.\")\n"
   ]
  }
 ],
 "metadata": {
  "kernelspec": {
   "display_name": "Python 3 (ipykernel)",
   "language": "python",
   "name": "python3"
  },
  "language_info": {
   "codemirror_mode": {
    "name": "ipython",
    "version": 3
   },
   "file_extension": ".py",
   "mimetype": "text/x-python",
   "name": "python",
   "nbconvert_exporter": "python",
   "pygments_lexer": "ipython3",
   "version": "3.10.8"
  }
 },
 "nbformat": 4,
 "nbformat_minor": 5
}
